Traceback (most recent call last):
  File "/home/lngo/anaconda3/envs/jupyter-book/lib/python3.10/site-packages/jupyter_cache/executors/utils.py", line 51, in single_nb_execution
    executenb(
  File "/home/lngo/anaconda3/envs/jupyter-book/lib/python3.10/site-packages/nbclient/client.py", line 1204, in execute
    return NotebookClient(nb=nb, resources=resources, km=km, **kwargs).execute()
  File "/home/lngo/anaconda3/envs/jupyter-book/lib/python3.10/site-packages/nbclient/util.py", line 84, in wrapped
    return just_run(coro(*args, **kwargs))
  File "/home/lngo/anaconda3/envs/jupyter-book/lib/python3.10/site-packages/nbclient/util.py", line 62, in just_run
    return loop.run_until_complete(coro)
  File "/home/lngo/anaconda3/envs/jupyter-book/lib/python3.10/asyncio/base_events.py", line 641, in run_until_complete
    return future.result()
  File "/home/lngo/anaconda3/envs/jupyter-book/lib/python3.10/site-packages/nbclient/client.py", line 663, in async_execute
    await self.async_execute_cell(
  File "/home/lngo/anaconda3/envs/jupyter-book/lib/python3.10/site-packages/nbclient/client.py", line 965, in async_execute_cell
    await self._check_raise_for_error(cell, cell_index, exec_reply)
  File "/home/lngo/anaconda3/envs/jupyter-book/lib/python3.10/site-packages/nbclient/client.py", line 862, in _check_raise_for_error
    raise CellExecutionError.from_cell_and_msg(cell, exec_reply_content)
nbclient.exceptions.CellExecutionError: An error occurred while executing the following cell:
------------------
c.
------------------

[0;36m  Input [0;32mIn [34][0;36m[0m
[0;31m    c.[0m
[0m      ^[0m
[0;31mSyntaxError[0m[0;31m:[0m invalid syntax

SyntaxError: invalid syntax (1195783164.py, line 1)

