Traceback (most recent call last):
  File "/home/cehrett/.conda/envs/jupyter-book/lib/python3.10/site-packages/jupyter_cache/executors/utils.py", line 58, in single_nb_execution
    executenb(
  File "/home/cehrett/.local/lib/python3.10/site-packages/nbclient/client.py", line 1319, in execute
    return NotebookClient(nb=nb, resources=resources, km=km, **kwargs).execute()
  File "/home/cehrett/.local/lib/python3.10/site-packages/jupyter_core/utils/__init__.py", line 165, in wrapped
    return loop.run_until_complete(inner)
  File "/home/cehrett/.conda/envs/jupyter-book/lib/python3.10/asyncio/base_events.py", line 649, in run_until_complete
    return future.result()
  File "/home/cehrett/.local/lib/python3.10/site-packages/nbclient/client.py", line 709, in async_execute
    await self.async_execute_cell(
  File "/home/cehrett/.local/lib/python3.10/site-packages/nbclient/client.py", line 1062, in async_execute_cell
    await self._check_raise_for_error(cell, cell_index, exec_reply)
  File "/home/cehrett/.local/lib/python3.10/site-packages/nbclient/client.py", line 918, in _check_raise_for_error
    raise CellExecutionError.from_cell_and_msg(cell, exec_reply_content)
nbclient.exceptions.CellExecutionError: An error occurred while executing the following cell:
------------------
import random
import numpy as np
import matplotlib.pyplot as plt
------------------


[0;31m---------------------------------------------------------------------------[0m
[0;31mImportError[0m                               Traceback (most recent call last)
Cell [0;32mIn[2], line 3[0m
[1;32m      1[0m [38;5;28;01mimport[39;00m[38;5;250m [39m[38;5;21;01mrandom[39;00m
[1;32m      2[0m [38;5;28;01mimport[39;00m[38;5;250m [39m[38;5;21;01mnumpy[39;00m[38;5;250m [39m[38;5;28;01mas[39;00m[38;5;250m [39m[38;5;21;01mnp[39;00m
[0;32m----> 3[0m [38;5;28;01mimport[39;00m[38;5;250m [39m[38;5;21;01mmatplotlib[39;00m[38;5;21;01m.[39;00m[38;5;21;01mpyplot[39;00m[38;5;250m [39m[38;5;28;01mas[39;00m[38;5;250m [39m[38;5;21;01mplt[39;00m

File [0;32m~/.conda/envs/jupyter-book/lib/python3.10/site-packages/matplotlib/__init__.py:161[0m
[1;32m    157[0m [38;5;28;01mfrom[39;00m[38;5;250m [39m[38;5;21;01mpackaging[39;00m[38;5;21;01m.[39;00m[38;5;21;01mversion[39;00m[38;5;250m [39m[38;5;28;01mimport[39;00m parse [38;5;28;01mas[39;00m parse_version
[1;32m    159[0m [38;5;66;03m# cbook must import matplotlib only within function[39;00m
[1;32m    160[0m [38;5;66;03m# definitions, so it is safe to import from it here.[39;00m
[0;32m--> 161[0m [38;5;28;01mfrom[39;00m[38;5;250m [39m[38;5;21;01m.[39;00m[38;5;250m [39m[38;5;28;01mimport[39;00m _api, _version, cbook, _docstring, rcsetup
[1;32m    162[0m [38;5;28;01mfrom[39;00m[38;5;250m [39m[38;5;21;01mmatplotlib[39;00m[38;5;21;01m.[39;00m[38;5;21;01m_api[39;00m[38;5;250m [39m[38;5;28;01mimport[39;00m MatplotlibDeprecationWarning
[1;32m    163[0m [38;5;28;01mfrom[39;00m[38;5;250m [39m[38;5;21;01mmatplotlib[39;00m[38;5;21;01m.[39;00m[38;5;21;01mrcsetup[39;00m[38;5;250m [39m[38;5;28;01mimport[39;00m cycler  [38;5;66;03m# noqa: F401[39;00m

File [0;32m~/.conda/envs/jupyter-book/lib/python3.10/site-packages/matplotlib/cbook.py:32[0m
[1;32m     29[0m     [38;5;28;01mfrom[39;00m[38;5;250m [39m[38;5;21;01mnumpy[39;00m[38;5;250m [39m[38;5;28;01mimport[39;00m VisibleDeprecationWarning
[1;32m     31[0m [38;5;28;01mimport[39;00m[38;5;250m [39m[38;5;21;01mmatplotlib[39;00m
[0;32m---> 32[0m [38;5;28;01mfrom[39;00m[38;5;250m [39m[38;5;21;01mmatplotlib[39;00m[38;5;250m [39m[38;5;28;01mimport[39;00m _api, _c_internal_utils
[1;32m     35[0m [38;5;28;01mclass[39;00m[38;5;250m [39m[38;5;21;01m_ExceptionInfo[39;00m:
[1;32m     36[0m [38;5;250m    [39m[38;5;124;03m"""[39;00m
[1;32m     37[0m [38;5;124;03m    A class to carry exception information around.[39;00m
[1;32m     38[0m 
[0;32m   (...)[0m
[1;32m     43[0m [38;5;124;03m    users and result in incorrect tracebacks.[39;00m
[1;32m     44[0m [38;5;124;03m    """[39;00m

[0;31mImportError[0m: /lib64/libstdc++.so.6: version `GLIBCXX_3.4.29' not found (required by /home/cehrett/.conda/envs/jupyter-book/lib/python3.10/site-packages/matplotlib/_c_internal_utils.cpython-310-x86_64-linux-gnu.so)

